Workbook

Sheet Mode d'emploi
A1: Base de données produits — Calibrage Q4 (Amazon France)
A3: Ton identifiant Amazon Partenaires : | B3: iphonehub210a-21 | C3: ← repris de tes liens. Vérifie que c'est bien le tien : sinon les commissions iront à quelqu'un d'autre.
A5: Qui remplit quoi
A6: • Toi : seulement la colonne jaune « ✍ Lien produit Amazon » (le lien court de la barre SiteStripe d'Amazon Partenaires).
A7: • Claude : tout le reste. Nom, textes de vente, prix, note, nombre d'avis, photos, formules, quantités, réglages du site.
A9: Comment mettre à jour un site
A10: 1. Dans l'onglet du site, colle ou remplace un lien Amazon (une ligne = un produit). Pour masquer un produit, mets « Afficher sur le site ? » à Non.
A11: 2. Enregistre et ferme le fichier.
A12: 3. Dis à Claude : « l'Excel est à jour ». Claude relit le fichier dans tes Téléchargements, ouvre les fiches Amazon, remplit les colonnes et reconstruit le site.
A13: 4. Refais glisser le dossier du site sur Netlify (onglet Deploys). Le lien du site ne change pas.
A15: Ce que chaque colonne pilote sur le site
A16: • Ordre des lignes = ordre d'affichage · Catégorie = filtres · Prix / Prix barré = prix et badge de réduction · Badge = étiquette sur la photo.
A17: • « Pourquoi on l'a choisi » = texte de vente de la carte · Points forts = liste de la fiche produit · Images = photos et galerie.
A18: • Formule minimale = dans quelles formules du calculateur le produit apparaît (Essentielle ⊂ Complète ⊂ Prestige).
... A27: • Les prix Amazon changent : ils sont présentés comme indicatifs, avec la date du relevé. Pour un site durable, Amazon demande des prix mis à jour automatiquement (API).

Sheet Thanksgiving - Boutique
A1: Thanksgiving · Site 1 : boutique multi-produits (La Table Dorée)
A2: Cet onglet contient tout ce que le site affiche. Toi : seulement la colonne jaune « Lien produit Amazon ». Claude : tout le reste. L'ordre des lignes = l'ordre d'affichage sur le site.
A3: Réglage | B3: Valeur (rédigée par Claude, modifiable)
A4: Nom du site (*italique*) | B4: La Table *Dorée* | AN4: brand
A5: Événement | B5: Thanksgiving | AN5: event
A6: Niche (pied de page) | B6: Sélection d'arts de la table de fête | AN6: niche
A7: Date de l'événement (AAAA-MM-JJ) | B7: 2026-11-26 | AN7: event_date
A8: Date limite de commande (AAAA-MM-JJ) | B8: 2026-11-22 | AN8: deadline
A9: Titre du hero (*italique*) | B9: Recevez comme au restaurant, *à la maison*. | AN9: h1
A10: Sous-titre du hero | B10: Assiettes en grès, verres ambrés, bougeoirs et chemin de table assortis, choisis parmi des produits très bien notés sur Amazon. Indiquez le nombre d'invités : on calcule la liste, vous ajoutez tout au panier en un clic. | AN10: lead
A11: Urgence : titre (*italique*) | B11: Black Friday tombe *le lendemain* de Thanksgiving. | AN11: urg_t
A12: Urgence : texte | B12: Si vous attendez les promos du 27 novembre, votre table arrivera après le dîner. Commandez avant le 22 novembre pour être livré à temps. | AN12: urg_p
A13: Formule Essentielle : description | B13: Le nécessaire pour une belle table. | AN13: d_ess
A14: Formule Complète : description | B14: La table de fête, dinde comprise. | AN14: d_com
A15: Formule Prestige : description | B15: Toute la table, avec la carafe design. | AN15: d_pre
A16: Nombre d'invités par défaut | B16: 6 | AN16: guests
A17: Formule par défaut | B17: Complète | AN17: tier
A18: Date du relevé des prix | B18: 30/09/2026 | AN18: price_date
A19: Couleurs / ambiance (info) | B19: Lin clair, bordeaux, doré, vert forêt | AN19: colors
A21: n | B21: show | C21: link | D21: name | E21: short | F21: brand | G21: cat | H21: price | I21: was | J21: disc | K21: rate | L21: nrev | M21: asin | N21: badge | O21: why | P21: bul | Q21: img | R21: more | S21: tier | T21: lot | U21: unit | V21: per | W21: feature | X21: hero | Y21: step | Z21: tip | AA21: kw | AB21: search | AC21: final | AD21: status | AE21: notes
A22: N° | B22: Afficher sur le site ? | C22: ✍ Lien produit Amazon (SiteStripe) | D22: Nom du produit | E22: Nom court | F22: Marque | G22: Catégorie (filtre) | H22: Prix indicatif (€) | I22: Prix barré (€) | J22: Réduction | K22: Note Amazon (/5) | L22: Nombre d'avis | M22: ASIN | N22: Badge | O22: Pourquoi on l'a choisi (texte de vente) | P22: Points forts (séparés par ;) | Q22: Image principale (URL) | R22: Autres images (URL ; URL) | S22: Formule minimale | T22: Taille du lot | U22: Unité | V22: 1 lot pour … invités (vide = 1 lot) | W22: Mise en avant ? | X22: Position dans le hero (1 à 4) | Y22: Étape du guide | Z22: Conseil de l'étape | AA22: Mots-clés Amazon (pour chercher) | AB22: Chercher sur Amazon | AC22: Lien final pour le site | AD22: Statut | AE22: Notes
A23: =ROW()-22 -> 1 | B23: Oui | C23: https://link.amazon/B0f7BvgnY | D23: Assiettes plates en grès émaillé, lot de 6 | E23: Assiettes | F23: Amazon Basics | G23: Vaisselle | H23: 30.25 | I23: 37.66 | J23: =IF(AND(ISNUMBER(H23),ISNUMBER(I23),I23>H23),1-H23/I23,"") -> 0.19676049 | K23: 4.5 | L23: 182 | M23: B0F4QJFY82 | O23: Le grès donne un rendu de restaurant et passe au lave-vaisselle. C'est la base de toute la table. | P23: Lot de 6 assiettes de 26,7 cm ; Micro-ondes et lave-vaisselle ; Grès émaillé ivoire, qui ne craint pas les taches | Q23: https://m.media-amazon.com/images/I/61LZdZUWE3L._AC_SL1500_.jpg | R23: https://m.media-amazon.com/images/I/51Pb08v7pmL.jpg ; https://m.media-amazon.com/images/I/41TONZmF+CL.jpg ; https://m.media-amazon.com/images/I/519e3iSU4KL.jpg | S23: Essentielle | T23: 6 | U23: assiettes | V23: 6 | W23: Oui | X23: 1 | Y23: 2. Les assiettes | Z23: Une assiette par invité, à 2 cm du bord, avec la serviette pliée posée dessus. | AA23: assiettes grès lot de 6 | AB23: =IF(AA23="","",HYPERLINK("https://www.amazon.fr/s?k="&SUBSTITUTE(TRIM(AA23)," ","+")&IF('Mode d''emploi'!$B$3<>"","&tag="&'Mode d''emploi'!$B$3,""),"Chercher sur Amazon")) -> Chercher sur Amazon | AC23: =IF(C23<>"",HYPERLINK(C23,"Lien produit"),IF(AA23="","",HYPERLINK("https://www.amazon.fr/s?k="&SUBSTITUTE(TRIM(AA23)," ","+")&IF('Mode d''emploi'!$B$3<>"","&tag="&'Mode d''emploi'!$B$3,""),"Recherche + tag"))) -> Lien produit | AD23: Validé | AE23: Note relevée : 4,5/5 (182 avis)
A24: =ROW()-22 -> 2 | B24: Oui | C24: https://link.amazon/B0gMFQTug | D24: Verres Duralex Picardie ambre, lot de 6 | E24: Verres ambrés | F24: Duralex | G24: Verres | H24: 12.99 | J24: =IF(AND(ISNUMBER(H24),ISNUMBER(I24),I24>H24),1-H24/I24,"") | K24: 4.6 | L24: 166 | M24: B00K24HHSW | N24: Petit prix | O24: Le verre des cafés français, en verre trempé. Sa teinte ambrée réchauffe la table à la lumière des bougies. | P24: 6 verres de 25 cl ; Verre trempé très résistant ; Duralex, marque française | Q24: https://m.media-amazon.com/images/I/61rCURWPlfL._AC_SL1500_.jpg | R24: https://m.media-amazon.com/images/I/519KAqZbhgL.jpg ; https://m.media-amazon.com/images/I/510GT92m8kL.jpg ; https://m.media-amazon.com/images/I/51unT7OVegL.jpg | S24: Essentielle | T24: 6 | U24: verres | V24: 6 | W24: Non | X24: 2 | Y24: 3. Les verres | Z24: En haut à droite de chaque assiette, un verre ambré par invité. | AA24: verres ambrés lot de 6 | AB24: =IF(AA24="","",HYPERLINK("https://www.amazon.fr/s?k="&SUBSTITUTE(TRIM(AA24)," ","+")&IF('Mode d''emploi'!$B$3<>"","&tag="&'Mode d''emploi'!$B$3,""),"Chercher sur Amazon")) -> Chercher sur Amazon | AC24: =IF(C24<>"",HYPERLINK(C24,"Lien produit"),IF(AA24="","",HYPERLINK("https://www.amazon.fr/s?k="&SUBSTITUTE(TRIM(AA24)," ","+")&IF('Mode d''emploi'!$B$3<>"","&tag="&'Mode d''emploi'!$B$3,""),"Recherche + tag"))) -> Lien produit | AD24: Validé
A25: =ROW()-22 -> 3 | B25: Oui | C25: https://link.amazon/A09WxWhqV | D25: Bougeoirs carrés en métal noir, lot de 4 | E25: Bougeoirs | F25: heimzeit | G25: Déco | H25: 16.99 | J25: =IF(AND(ISNUMBER(H25),ISNUMBER(I25),I25>H25),1-H25/I25,"") | K25: 4.6 | L25: 196 | M25: B0CJJS1KRR | O25: Des chandelles alignées sur le chemin de table : l'effet dîner de fête immédiat, pour moins de 17 €. | P25: Lot de 4, 5 × 5 cm ; Pour bougies de Ø 22 mm ; Fer enduit, résistant à la rouille | Q25: https://m.media-amazon.com/images/I/61UFEOLJbxL._AC_SL1500_.jpg | R25: https://m.media-amazon.com/images/I/51GvJANh65L.jpg ; https://m.media-amazon.com/images/I/316lH6njzjL.jpg | S25: Essentielle | T25: 4 | U25: bougeoirs | V25: 8 | W25: Non | X25: 3 | Y25: 4. La lumière | Z25: Les bougeoirs alignés sur le chemin. Le plat de dinde au centre, au moment du service. | AA25: bougeoirs métal lot de 4 | AB25: =IF(AA25="","",HYPERLINK("https://www.amazon.fr/s?k="&SUBSTITUTE(TRIM(AA25)," ","+")&IF('Mode d''emploi'!$B$3<>"","&tag="&'Mode d''emploi'!$B$3,""),"Chercher sur Amazon")) -> Chercher sur Amazon | AC25: =IF(C25<>"",HYPERLINK(C25,"Lien produit"),IF(AA25="","",HYPERLINK("https://www.amazon.fr/s?k="&SUBSTITUTE(TRIM(AA25)," ","+")&IF('Mode d''emploi'!$B$3<>"","&tag="&'Mode d''emploi'!$B$3,""),"Recherche + tag"))) -> Lien produit | AD25: Validé
A26: =ROW()-22 -> 4 | B26: Oui | C26: https://link.amazon/A0dfoxWJ8 | D26: Chemin de table en rouleau, 30 cm × 25 m | E26: Chemin de table | F26: 100%Mosel | G26: Déco | H26: 19.99 | I26: 21.99 | J26: =IF(AND(ISNUMBER(H26),ISNUMBER(I26),I26>H26),1-H26/I26,"") -> 0.090950432 | K26: 4.7 | L26: 9879 | M26: B0CNTZT6ST | N26: 9 800+ avis | O26: Coupé à la longueur exacte de votre table. Le bleu nuit fait ressortir l'ivoire des assiettes et l'ambre des verres. | P26: Rouleau de 30 cm × 25 m ; Se découpe aux ciseaux ; Tissu non tissé léger | Q26: https://m.media-amazon.com/images/I/81j20kkyDKL._AC_SL1500_.jpg | R26: https://m.media-amazon.com/images/I/41pP7B4zyVL.jpg ; https://m.media-amazon.com/images/I/41S-uISZXKL.jpg | S26: Essentielle | T26: 1 | U26: rouleau de 25 m | W26: Non | Y26: 1. Le chemin de table | Z26: Déroulez-le au centre et coupez-le 20 cm plus long de chaque côté de la table. | AA26: chemin de table rouleau | AB26: =IF(AA26="","",HYPERLINK("https://www.amazon.fr/s?k="&SUBSTITUTE(TRIM(AA26)," ","+")&IF('Mode d''emploi'!$B$3<>"","&tag="&'Mode d''emploi'!$B$3,""),"Chercher sur Amazon")) -> Chercher sur Amazon | AC26: =IF(C26<>"",HYPERLINK(C26,"Lien produit"),IF(AA26="","",HYPERLINK("https://www.amazon.fr/s?k="&SUBSTITUTE(TRIM(AA26)," ","+")&IF('Mode d''emploi'!$B$3<>"","&tag="&'Mode d''emploi'!$B$3,""),"Recherche + tag"))) -> Lien produit | AD26: Validé | AE26: Couleur bleu nuit. Existe peut-être en bordeaux ou doré sur la même fiche.
A27: =ROW()-22 -> 5 | B27: Oui | C27: https://link.amazon/B06UH3b7d | D27: Plat de service ovale Mikasa en grès, 39 cm | E27: Plat de service | F27: Mikasa | G27: Vaisselle | H27: 40.38 | J27: =IF(AND(ISNUMBER(H27),ISNUMBER(I27),I27>H27),1-H27/I27,"") | K27: 4.4 | L27: 37 | M27: B0CH176764 | N27: Pour la dinde | O27: 39 cm pour présenter la dinde découpée ou les accompagnements au centre de la table. | P27: Plat ovale de 39 cm ; Grès crème aux bords festonnés ; Micro-ondes et lave-vaisselle | Q27: https://m.media-amazon.com/images/I/41Veuj0kqIL._AC_SL1500_.jpg | R27: https://m.media-amazon.com/images/I/41KsppeqlyL.jpg ; https://m.media-amazon.com/images/I/414paO8DXrL.jpg ; https://m.media-amazon.com/images/I/51PS5cULdtL.jpg | S27: Complète | T27: 1 | U27: plat | W27: Non | X27: 4 | AA27: plat de service ovale grès | AB27: =IF(AA27="","",HYPERLINK("https://www.amazon.fr/s?k="&SUBSTITUTE(TRIM(AA27)," ","+")&IF('Mode d''emploi'!$B$3<>"","&tag="&'Mode d''emploi'!$B$3,""),"Chercher sur Amazon")) -> Chercher sur Amazon | AC27: =IF(C27<>"",HYPERLINK(C27,"Lien produit"),IF(AA27="","",HYPERLINK("https://www.amazon.fr/s?k="&SUBSTITUTE(TRIM(AA27)," ","+")&IF('Mode d''emploi'!$B$3<>"","&tag="&'Mode d''emploi'!$B$3,""),"Recherche + tag"))) -> Lien produit | AD27: Validé
A28: =ROW()-22 -> 6 | B28: Oui | C28: https://link.amazon/B0iwpYq7J | D28: Porte-noms de table dorés, lot de 10 | E28: Porte-noms | F28: LDHHYH | G28: Déco | H28: 39.3 | J28: =IF(AND(ISNUMBER(H28),ISNUMBER(I28),I28>H28),1-H28/I28,"") | K28: 5 | L28: 10 | M28: B0CJX7HYSQ | N28: Nouveau | O28: Chaque invité trouve sa place. Un détail de mariage qui fait tout son effet à Thanksgiving. | P28: Lot de 10, hauteur 19 cm ; Acier inoxydable doré ; Base antidérapante | Q28: https://m.media-amazon.com/images/I/61WevwooYYL._AC_SL1500_.jpg | R28: https://m.media-amazon.com/images/I/41pgUYmsKML.jpg ; https://m.media-amazon.com/images/I/41RLTvM2PrL.jpg | S28: Complète | T28: 10 | U28: porte-noms | V28: 10 | W28: Non | AA28: porte nom table doré | AB28: =IF(AA28="","",HYPERLINK("https://www.amazon.fr/s?k="&SUBSTITUTE(TRIM(AA28)," ","+")&IF('Mode d''emploi'!$B$3<>"","&tag="&'Mode d''emploi'!$B$3,""),"Chercher sur Amazon")) -> Chercher sur Amazon | AC28: =IF(C28<>"",HYPERLINK(C28,"Lien produit"),IF(AA28="","",HYPERLINK("https://www.amazon.fr/s?k="&SUBSTITUTE(TRIM(AA28)," ","+")&IF('Mode d''emploi'!$B$3<>"","&tag="&'Mode d''emploi'!$B$3,""),"Recherche + tag"))) -> Lien produit | AD28: Validé | AE28: Seulement 10 avis sur Amazon.
A29: =ROW()-22 -> 7 | B29: Oui | C29: https://link.amazon/A0ifRWvCt | D29: Carafe filtrante Aarke Purifier, 2,4 L | E29: Carafe Aarke | F29: Aarke | G29: Verres | H29: 155 | J29: =IF(AND(ISNUMBER(H29),ISNUMBER(I29),I29>H29),1-H29/I29,"") | K29: 4.1 | L29: 133 | M29: B0BTZ66WG2 | N29: Premium | O29: La carafe design qui filtre l'eau du robinet. Belle sur la table, utile toute l'année. | P29: 2,4 litres ; Verre et acier, sans plastique ; 3 recharges de filtre incluses | Q29: https://m.media-amazon.com/images/I/713jflGlKdL._AC_SL1500_.jpg | R29: https://m.media-amazon.com/images/I/41WOJI-jggL.jpg ; https://m.media-amazon.com/images/I/414h9FwbWnL.jpg | S29: Prestige | T29: 1 | U29: carafe | W29: Non | AA29: carafe verre | AB29: =IF(AA29="","",HYPERLINK("https://www.amazon.fr/s?k="&SUBSTITUTE(TRIM(AA29)," ","+")&IF('Mode d''emploi'!$B$3<>"","&tag="&'Mode d''emploi'!$B$3,""),"Chercher sur Amazon")) -> Chercher sur Amazon | AC29: =IF(C29<>"",HYPERLINK(C29,"Lien produit"),IF(AA29="","",HYPERLINK("https://www.amazon.fr/s?k="&SUBSTITUTE(TRIM(AA29)," ","+")&IF('Mode d''emploi'!$B$3<>"","&tag="&'Mode d''emploi'!$B$3,""),"Recherche + tag"))) -> Lien produit | AD29: Validé | AE29: Chère (155 €) : réservée à la formule Prestige.
A30: =ROW()-22 -> 8 | B30: Non | C30: https://link.amazon/A06301FIk | D30: Serviettes Möve Superwuschel, lot de 3 | E30: Serviettes | F30: Möve | G30: Déco | H30: 50.85 | J30: =IF(AND(ISNUMBER(H30),ISNUMBER(I30),I30>H30),1-H30/I30,"") | K30: 4.5 | L30: 725 | M30: B07YVNXJ5F | P30: 50 × 100 cm ; 100 % coton ; Lavables à 60 °C | Q30: https://m.media-amazon.com/images/I/91LaQKtRRHL._AC_SL1500_.jpg | R30: https://m.media-amazon.com/images/I/51QDNk8g05L.jpg ; https://m.media-amazon.com/images/I/51jkfUrq1vL.jpg | S30: Essentielle | T30: 6 | U30: serviettes | V30: 6 | W30: Non | AA30: serviettes de table lin lot de 6 | AB30: =IF(AA30="","",HYPERLINK("https://www.amazon.fr/s?k="&SUBSTITUTE(TRIM(AA30)," ","+")&IF('Mode d''emploi'!$B$3<>"","&tag="&'Mode d''emploi'!$B$3,""),"Chercher sur Amazon")) -> Chercher sur Amazon | AC30: =IF(C30<>"",HYPERLINK(C30,"Lien produit"),IF(AA30="","",HYPERLINK("https://www.amazon.fr/s?k="&SUBSTITUTE(TRIM(AA30)," ","+")&IF('Mode d''emploi'!$B$3<>"","&tag="&'Mode d''emploi'!$B$3,""),"Recherche + tag"))) -> Lien produit | AD30: À remplacer | AE30: Ce sont des serviettes de TOILETTE. Colle ici le lien de serviettes de table en lin (lot de 6) : Claude remplira le reste et passera la ligne à « Oui ».
A38: Légende : jaune = à remplir par toi (le lien Amazon) · crème = rédigé par Claude · bleu = calculé · ligne grise = masquée sur le site.

Sheet Thanksgiving - Produit unique
A1: Thanksgiving · Site 2 : site d'un seul produit (Juste Cuisson · MEATER)
A2: Toi : seulement les cellules jaunes (liens Amazon), si tu veux mettre tes propres liens SiteStripe. Claude : tout le reste. Chaque tableau se lit de haut en bas, dans l'ordre d'affichage.
A4: 1. Réglages du site
A5: Nom du site (*italique*) | B5: Juste *Cuisson* | AN5: brand
A6: Niche (pied de page) | B6: Thermomètre à viande sans fil pour Thanksgiving | AN6: niche
A7: Événement | B7: Thanksgiving | AN7: event
A8: Date de l'événement (AAAA-MM-JJ) | B8: 2026-11-26 | AN8: event_date
A9: Date limite de commande (AAAA-MM-JJ) | B9: 2026-11-22 | AN9: deadline
A10: Date du relevé des prix | B10: 30/09/2026 | AN10: price_date
A11: Sur-titre du produit | B11: Édition Thanksgiving 2026 | AN11: eyebrow
A12: Accroche sous le nom du produit | B12: Le thermomètre 100 % sans fil qui surveille votre dinde à votre place. Vous restez à table, il vous prévient quand c'est cuit. | AN12: tagline
A13: 3 arguments rapides (séparés par ;) | B13: Sonde 100 % sans fil : le four reste fermé ; Alerte sur votre téléphone, jusqu'à 50 m ; Appli gratuite en français, cuisson guidée | AN13: quick
A14: Grand bandeau : titre (*italique*) | B14: Cette année, la dinde *ne sera pas sèche*. | AN14: banner_t
A15: Grand bandeau : texte | B15: Le jeudi 26 novembre, il y aura toute la famille. Et il y aura votre dinde : dorée dehors, juteuse à cœur, servie à l'heure. | AN15: banner_p
A16: Problème : titre (*italique*) | B16: Ouvrir le four toutes les dix minutes, *c'est rater la dinde*. | AN16: problem_t
... A21: Appel final : texte | B21: Commandez avant le 22 novembre pour être livré à temps. Il reste : | AN21: final_p
A23: 2. Les modèles proposés (le visiteur choisit ; « Par défaut » = Oui sur un seul) | AN23: table:variants
A24: badge | B24: name | C24: link | D24: desc | E24: price | F24: was | G24: rate | H24: nrev | I24: asin | J24: img | K24: default
A25: Badge | B25: Nom du modèle | C25: ✍ Lien Amazon | D25: Description courte | E25: Prix indicatif (€) | F25: Prix barré (€) | G25: Note /5 | H25: Nombre d'avis | I25: ASIN | J25: Image (URL) | K25: Par défaut ?
A26: L'essentiel | B26: MEATER SE | C26: https://www.amazon.fr/dp/B0D2LQGJ2V?tag=iphonehub210a-21 | D26: 1 sonde sans fil, portée Bluetooth jusqu'à 50 m, cuisson guidée dans l'appli. Le modèle d'entrée de gamme. | E26: 85 | G26: 4.3 | H26: 2655 | I26: B0D2LQGJ2V | J26: https://m.media-amazon.com/images/I/61lT6LnsjXL._AC_SL1500_.jpg | K26: Non
A27: Notre choix | B27: MEATER Plus | C27: https://www.amazon.fr/dp/B07H8WTFHW?tag=iphonehub210a-21 | D27: 1 sonde 100 % sans fil, Bluetooth et Wi-Fi via MEATER Cloud, portée jusqu'à 50 m. Le plus noté des trois. | E27: 99 | G27: 4.5 | H27: 45434 | I27: B07H8WTFHW | J27: https://m.media-amazon.com/images/I/61C9DAvebML._AC_SL1500_.jpg | K27: Oui
A28: Grande tablée | B28: MEATER Block (4 sondes) | C28: https://www.amazon.fr/dp/B07TJ95CBM?tag=iphonehub210a-21 | D28: 4 sondes pour la dinde et les accompagnements en même temps. Relais Bluetooth intégré, fonctionne même sans téléphone. | E28: 239 | G28: 4 | H28: 6966 | I28: B07TJ95CBM | J28: https://m.media-amazon.com/images/I/61UoSbiv5pL._AC_SL1500_.jpg | K28: Non
A30: 3. Photos du produit principal (la 1re est la photo principale) | AN30: table:gallery
A31: img | B31: alt
A32: Image (URL) | B32: Description de la photo
A33: https://m.media-amazon.com/images/I/61C9DAvebML._AC_SL1500_.jpg | B33: MEATER Plus, photo 1
A34: https://m.media-amazon.com/images/I/81eV7iIexdL._AC_SL1500_.jpg | B34: MEATER Plus, photo 2
A35: https://m.media-amazon.com/images/I/81wkZSDjXuL._AC_SL1500_.jpg | B35: MEATER Plus, photo 3
A36: https://m.media-amazon.com/images/I/815wTsnsBQL._AC_SL1500_.jpg | B36: MEATER Plus, photo 4
A37: https://m.media-amazon.com/images/I/81XsgqCQZFL._AC_SL1500_.jpg | B37: MEATER Plus, photo 5
A38: https://m.media-amazon.com/images/I/71ob5DdqsbL._AC_SL1500_.jpg | B38: MEATER Plus, photo 6
A39: https://m.media-amazon.com/images/I/81JWYW9cQFL._AC_SL1500_.jpg | B39: MEATER Plus, photo 7
A40: https://m.media-amazon.com/images/I/71Ryd62dTGL._AC_SL1500_.jpg | B40: MEATER Plus, photo 8
A42: 4. Bénéfices (6) | AN42: table:benefits
A43: title | B43: text
A44: Titre | B44: Texte
A45: Le four reste fermé | B45: La sonde 100 % sans fil reste plantée dans la dinde du début à la fin. Plus besoin d'ouvrir pour vérifier.
A46: Alerte sur votre téléphone | B46: Vous êtes prévenu quand la température cible est atteinte, jusqu'à 50 m du four.
A47: 2 capteurs en 1 | B47: La température à cœur de la viande (jusqu'à 100 °C) et celle du four (jusqu'à 275 °C), en même temps.
A48: Cuisson guidée | B48: L'appli gratuite, en français, vous guide étape par étape et vous dit quand sortir la viande.
...

Sheet Black Friday - Boutique
A1: Black Friday · Site 1 : boutique multi-produits
A2: Réglages du site (modifiables)
B3: Site
A4: Nom du site | B4: VOLTA
A5: Niche | B5: Audio et accessoires
A6: Accroche principale | B6: Le son −50 %. Une semaine.
A7: Offre mise en avant | B7: Jusqu'à −50 % sur l'audio
A8: Date limite (compte à rebours) | B8: 2026-11-29
A9: Couleurs / ambiance | B9: Fond #0c0c0d · accent #ffd21f · sombre
A11: N° | B11: Site | C11: Nom du produit | D11: Catégorie | E11: Description courte | F11: Points forts (séparés par ;) | G11: Prix indicatif (€) | H11: Prix barré (€) | I11: Réduction | J11: Badge | K11: Dans le pack ? | L11: Mots-clés Amazon | M11: Chercher sur Amazon | N11: Lien produit Amazon (SiteStripe) | O11: Image principale (URL) | P11: Image collée | Q11: Lien final pour le site | R11: Statut | S11: Notes
A12: =ROW()-11 -> 1 | B12: VOLTA | C12: Casque sans fil à réduction de bruit | D12: Casques | E12: Réduction de bruit active hybride, 40 h d'autonomie, charge rapide : 10 min pour 5 h d'écoute. | F12: ANC hybride, mode transparence ; 40 h d'autonomie ; Bluetooth 5.3 multipoint | G12: 129 | H12: 259 | I12: =IF(AND(ISNUMBER(G12),ISNUMBER(H12),H12>G12),1-G12/H12,"") -> 0.5019305 | J12: −50 % | K12: Oui | L12: casque bluetooth réduction de bruit | M12: =IF(L12="","",HYPERLINK("https://www.amazon.fr/s?k="&SUBSTITUTE(TRIM(L12)," ","+")&IF('Mode d''emploi'!$B$3<>"","&tag="&'Mode d''emploi'!$B$3,""),"Chercher sur Amazon")) -> Chercher sur Amazon | Q12: =IF(N12<>"",HYPERLINK(N12,"Lien produit"),IF(L12="","",HYPERLINK("https://www.amazon.fr/s?k="&SUBSTITUTE(TRIM(L12)," ","+")&IF('Mode d''emploi'!$B$3<>"","&tag="&'Mode d''emploi'!$B$3,""),"Recherche + tag"))) -> Recherche + tag | R12: À trouver
A13: =ROW()-11 -> 2 | B13: VOLTA | C13: Écouteurs sans fil à réduction de bruit | D13: Écouteurs | E13: Écouteurs à réduction de bruit, étanches à la sueur et à la pluie. 30 h avec le boîtier. | F13: ANC jusqu'à −35 dB ; IPX5 ; Boîtier à charge sans fil | G13: 69 | H13: 129 | I13: =IF(AND(ISNUMBER(G13),ISNUMBER(H13),H13>G13),1-G13/H13,"") -> 0.46511628 | J13: Aucun | K13: Oui | L13: écouteurs sans fil réduction de bruit | M13: =IF(L13="","",HYPERLINK("https://www.amazon.fr/s?k="&SUBSTITUTE(TRIM(L13)," ","+")&IF('Mode d''emploi'!$B$3<>"","&tag="&'Mode d''emploi'!$B$3,""),"Chercher sur Amazon")) -> Chercher sur Amazon | Q13: =IF(N13<>"",HYPERLINK(N13,"Lien produit"),IF(L13="","",HYPERLINK("https://www.amazon.fr/s?k="&SUBSTITUTE(TRIM(L13)," ","+")&IF('Mode d''emploi'!$B$3<>"","&tag="&'Mode d''emploi'!$B$3,""),"Recherche + tag"))) -> Recherche + tag | R13: À trouver
A14: =ROW()-11 -> 3 | B14: VOLTA | C14: Enceinte Bluetooth étanche | D14: Enceintes | E14: Petite, étanche, puissante. Elle flotte, résiste au sable et tient 20 h. | F14: IP67 ; 20 h d'autonomie ; Couplage stéréo avec une 2e enceinte | G14: 59 | H14: 99 | I14: =IF(AND(ISNUMBER(G14),ISNUMBER(H14),H14>G14),1-G14/H14,"") -> 0.4040404 | J14: Aucun | K14: Non | L14: enceinte bluetooth étanche | M14: =IF(L14="","",HYPERLINK("https://www.amazon.fr/s?k="&SUBSTITUTE(TRIM(L14)," ","+")&IF('Mode d''emploi'!$B$3<>"","&tag="&'Mode d''emploi'!$B$3,""),"Chercher sur Amazon")) -> Chercher sur Amazon | Q14: =IF(N14<>"",HYPERLINK(N14,"Lien produit"),IF(L14="","",HYPERLINK("https://www.amazon.fr/s?k="&SUBSTITUTE(TRIM(L14)," ","+")&IF('Mode d''emploi'!$B$3<>"","&tag="&'Mode d''emploi'!$B$3,""),"Recherche + tag"))) -> Recherche + tag | R14: À trouver
A15: =ROW()-11 -> 4 | B15: VOLTA | C15: Barre de son TV avec caisson | D15: Enceintes | E15: Barre de son 2.1 avec caisson intégré. Un seul câble HDMI et le son de votre TV change complètement. | F15: HDMI eARC ; Mode dialogue ; Installation en 2 minutes | G15: 149 | H15: 279 | I15: =IF(AND(ISNUMBER(G15),ISNUMBER(H15),H15>G15),1-G15/H15,"") -> 0.46594982 | J15: Stock limité | K15: Non | L15: barre de son tv caisson | M15: =IF(L15="","",HYPERLINK("https://www.amazon.fr/s?k="&SUBSTITUTE(TRIM(L15)," ","+")&IF('Mode d''emploi'!$B$3<>"","&tag="&'Mode d''emploi'!$B$3,""),"Chercher sur Amazon")) -> Chercher sur Amazon | Q15: =IF(N15<>"",HYPERLINK(N15,"Lien produit"),IF(L15="","",HYPERLINK("https://www.amazon.fr/s?k="&SUBSTITUTE(TRIM(L15)," ","+")&IF('Mode d''emploi'!$B$3<>"","&tag="&'Mode d''emploi'!$B$3,""),"Recherche + tag"))) -> Recherche + tag | R15: À trouver
A16: =ROW()-11 -> 5 | B16: VOLTA | C16: Montre connectée GPS | D16: Accessoires | E16: Suivi sport et sommeil, GPS intégré, 10 jours d'autonomie et notifications de votre téléphone. | F16: GPS intégré ; 10 jours d'autonomie ; Étanche 5 ATM | G16: 89 | H16: 169 | I16: =IF(AND(ISNUMBER(G16),ISNUMBER(H16),H16>G16),1-G16/H16,"") -> 0.47337278 | J16: Aucun | K16: Non | L16: montre connectée gps | M16: =IF(L16="","",HYPERLINK("https://www.amazon.fr/s?k="&SUBSTITUTE(TRIM(L16)," ","+")&IF('Mode d''emploi'!$B$3<>"","&tag="&'Mode d''emploi'!$B$3,""),"Chercher sur Amazon")) -> Chercher sur Amazon | Q16: =IF(N16<>"",HYPERLINK(N16,"Lien produit"),IF(L16="","",HYPERLINK("https://www.amazon.fr/s?k="&SUBSTITUTE(TRIM(L16)," ","+")&IF('Mode d''emploi'!$B$3<>"","&tag="&'Mode d''emploi'!$B$3,""),"Recherche + tag"))) -> Recherche + tag | R16: À trouver
A17: =ROW()-11 -> 6 | B17: VOLTA | C17: Batterie externe 20 000 mAh | D17: Accessoires | E17: Recharge un ordinateur portable, un téléphone et des écouteurs en même temps. | F17: 65 W USB-C ; 3 ports ; 4 recharges de téléphone | G17: 29 | H17: 49 | I17: =IF(AND(ISNUMBER(G17),ISNUMBER(H17),H17>G17),1-G17/H17,"") -> 0.40816327 | J17: Aucun | K17: Oui | L17: batterie externe 20000mah 65w | M17: =IF(L17="","",HYPERLINK("https://www.amazon.fr/s?k="&SUBSTITUTE(TRIM(L17)," ","+")&IF('Mode d''emploi'!$B$3<>"","&tag="&'Mode d''emploi'!$B$3,""),"Chercher sur Amazon")) -> Chercher sur Amazon | Q17: =IF(N17<>"",HYPERLINK(N17,"Lien produit"),IF(L17="","",HYPERLINK("https://www.amazon.fr/s?k="&SUBSTITUTE(TRIM(L17)," ","+")&IF('Mode d''emploi'!$B$3<>"","&tag="&'Mode d''emploi'!$B$3,""),"Recherche + tag"))) -> Recherche + tag | R17: À trouver
A18: =ROW()-11 -> 7 | B18: VOLTA | C18: Chargeur USB-C 65 W GaN | D18: Accessoires | E18: Charge ordinateur, téléphone et tablette avec un seul chargeur compact. | F18: 65 W ; 3 ports ; Format compact | G18: 32 | H18: 49 | I18: =IF(AND(ISNUMBER(G18),ISNUMBER(H18),H18>G18),1-G18/H18,"") -> 0.34693878 | J18: Aucun | K18: Non | L18: chargeur usb c 65w gan | M18: =IF(L18="","",HYPERLINK("https://www.amazon.fr/s?k="&SUBSTITUTE(TRIM(L18)," ","+")&IF('Mode d''emploi'!$B$3<>"","&tag="&'Mode d''emploi'!$B$3,""),"Chercher sur Amazon")) -> Chercher sur Amazon | Q18: =IF(N18<>"",HYPERLINK(N18,"Lien produit"),IF(L18="","",HYPERLINK("https://www.amazon.fr/s?k="&SUBSTITUTE(TRIM(L18)," ","+")&IF('Mode d''emploi'!$B$3<>"","&tag="&'Mode d''emploi'!$B$3,""),"Recherche + tag"))) -> Recherche + tag | R18: À trouver
A19: =ROW()-11 -> 8 | B19: VOLTA | C19: Casque enfant volume limité | D19: Casques | E19: Casque sans fil pour enfant, volume limité à 85 dB. | F19: Volume limité 85 dB ; 40 h ; Pliable | G19: 29 | H19: 45 | I19: =IF(AND(ISNUMBER(G19),ISNUMBER(H19),H19>G19),1-G19/H19,"") -> 0.35555556 | J19: Idée cadeau | K19: Non | L19: casque bluetooth enfant volume limité | M19: =IF(L19="","",HYPERLINK("https://www.amazon.fr/s?k="&SUBSTITUTE(TRIM(L19)," ","+")&IF('Mode d''emploi'!$B$3<>"","&tag="&'Mode d''emploi'!$B$3,""),"Chercher sur Amazon")) -> Chercher sur Amazon | Q19: =IF(N19<>"",HYPERLINK(N19,"Lien produit"),IF(L19="","",HYPERLINK("https://www.amazon.fr/s?k="&SUBSTITUTE(TRIM(L19)," ","+")&IF('Mode d''emploi'!$B$3<>"","&tag="&'Mode d''emploi'!$B$3,""),"Recherche + tag"))) -> Recherche + tag | R19: À trouver
A21: Prix indicatifs : ajustez-les au prix réel affiché sur Amazon.

Sheet Black Friday - Produit unique
A1: Black Friday · Site 2 : site d'un seul produit
A2: Tout est pré-rempli sauf les liens et les images. Jaune = à remplir ou vérifier · bleu = calculé.
A4: 1. Réglages du site
A5: Nom du site | B5: Aéra
A6: Niche | B6: Brosse soufflante 5 en 1
A7: Offre mise en avant | B7: Jusqu'à −40 % pendant le Black Friday
A8: Date limite (compte à rebours) | B8: 2026-11-29
A9: Couleurs / ambiance | B9: Fond rose poudré · accent noir · ambiance salon de beauté
A11: 2. Le produit
A12: Nom du produit | B12: Brosse soufflante 5 en 1 ionique
A13: Promesse (titre du hero) | B13: Le brushing de salon en 15 minutes, chez vous.
A14: Sous-titre | B14: Sèche, lisse, boucle et donne du volume avec un seul appareil. Prix Black Friday jusqu'au 29 novembre.
A15: Problème résolu | B15: Sèche-cheveux, lisseur, fer à boucler : trois appareils, 45 minutes le matin et des cheveux abîmés par la chaleur.
A16: Prix indicatif (€) | B16: 59.9
A17: Prix barré (€) | B17: 99.9
A18: Réduction | B18: =IF(AND(ISNUMBER(B16),ISNUMBER(B17),B17>B16),1-B16/B17,"") -> 0.4004004
A19: Mots-clés Amazon | B19: brosse soufflante 5 en 1 ionique
A20: Chercher sur Amazon | B20: =HYPERLINK("https://www.amazon.fr/s?k="&SUBSTITUTE(TRIM(B19)," ","+")&IF('Mode d''emploi'!$B$3<>"","&tag="&'Mode d''emploi'!$B$3,""),"Chercher sur Amazon") -> Chercher sur Amazon
A21: Lien produit Amazon (SiteStripe)
A22: Lien final pour le site | B22: =IF(B21<>"",HYPERLINK(B21,"Lien produit"),HYPERLINK("https://www.amazon.fr/s?k="&SUBSTITUTE(TRIM(B19)," ","+")&IF('Mode d''emploi'!$B$3<>"","&tag="&'Mode d''emploi'!$B$3,""),"Recherche + tag")) -> Recherche + tag
A23: Vidéo (URL, facultatif)
A25: 3. Images (6 conseillées, format carré)
A26: Image | B26: URL de l'image | F26: Image collée
A27: Principale (produit seul, fond blanc)
A28: En situation / lifestyle
A29: Détail / gros plan
A30: Avant / après ou résultat
A31: Contenu de la boîte
A32: Dimensions ou comparaison
A34: 4. Bénéfices (6)
A35: 5 embouts | B35: Sécher, lisser, boucler à gauche et à droite, donner du volume.
A36: Technologie ionique | B36: Moins de frisottis, cheveux plus brillants.
A37: 3 températures | B37: Adaptée aux cheveux fins, épais ou colorés.
A38: Moins de chaleur | B38: Coiffe à l'air chaud au lieu d'une plaque brûlante.
A39: Gain de temps | B39: Séchage et coiffage en une seule étape.
A40: Légère | B40: Se tient facilement, même bras levés.
A42: 5. Comment ça marche (3 étapes)
A43: Séchez à 80 % | B43: Avec l'embout séchage.
A44: Choisissez l'embout | B44: Lisse, boucles ou volume.
A45: Coiffez mèche par mèche | B45: Finissez à l'air froid pour fixer.
...

Sheet Prompt agent
A1: Texte à copier-coller dans ton agent de vibe coding, avec ce fichier joint. Remplace [ÉVÉNEMENT] par l'événement.
A3: PROMPT 1 — BOUTIQUE MULTI-PRODUITS
A5: Je te joins une base de données Excel de produits Amazon (France). Utilise UNIQUEMENT ces données : ne cherche pas d'autres produits ni d'autres images.
A6: Onglet : « [ÉVÉNEMENT] - Boutique ». En haut : les réglages du site (nom, titre du hero avec *italique*, sous-titre, message d'urgence, dates, descriptions des formules, invités et formule par défaut). Dessous : un produit par ligne, dans l'ordre d'affichage. Ignore les lignes où « Afficher sur le site ? » = Non.
A7: Pour chaque produit : nom, nom court, marque, catégorie (filtres), prix indicatif et prix barré (badge de réduction), note et nombre d'avis (étoiles), badge, « Pourquoi on l'a choisi » (texte de la carte), points forts séparés par ; (fiche produit), image principale et autres images (galerie). Le bouton « Voir sur Amazon » ouvre « Lien produit Amazon » dans un nouvel onglet.
A8: Calculateur de table : le visiteur choisit le nombre d'invités (4 à 12) et une formule. Un produit fait partie de sa « Formule minimale » et des formules supérieures (Essentielle ⊂ Complète ⊂ Prestige). Quantité = arrondi supérieur (invités ÷ « 1 lot pour … invités »), ou 1 si la case est vide. Le visiteur peut décocher ce qu'il possède déjà.
A9: Bouton « Tout ajouter à mon panier Amazon » : https://www.amazon.fr/gp/aws/cart/add.html?AssociateTag=[TAG]&ASIN.1=…&Quantity.1=…, avec l'ASIN de chaque produit coché et le tag de l'onglet « Mode d'emploi ».
A10: Aussi : produit « Mise en avant » en grande carte, objets « Position dans le hero » disposés comme une table dressée, guide « Étape du guide » + « Conseil de l'étape », compte à rebours vers la date limite, FAQ, rappel e-mail, barre d'achat collante sur mobile.
A12: PROMPT 2 — SITE D'UN SEUL PRODUIT
A14: Onglet : « [ÉVÉNEMENT] - Produit unique ». Construis une page de vente longue pour ce seul produit, avec UNIQUEMENT ces données et ces images : hero (promesse + image + prix + bouton), problème résolu, bénéfices, galerie, comment ça marche en 3 étapes, choix de la variante (chaque variante a son lien Amazon), caractéristiques et contenu de la boîte, accessoires, garantie, FAQ, rappel final avec compte à rebours. Bouton d'achat collant en bas sur mobile.
A16: POUR LES DEUX SITES
A17: Pied de page : « En tant que Partenaire Amazon, je réalise un bénéfice sur les achats remplissant les conditions requises. » Prix présentés comme indicatifs, avec la date du relevé. Liens Amazon avec rel="nofollow sponsored".

Sheet Listes
A1: Badge | B1: Oui/Non | C1: Statut | D1: Formule | E1: Catégorie
A2: Best-seller | B2: Oui | C2: À trouver | D2: Essentielle | E2: Vaisselle
A3: Nouveau | B3: Non | C3: En cours | D3: Complète | E3: Verres
A4: Stock limité | C4: Validé | D4: Prestige | E4: Déco
A5: Idée cadeau | C5: À remplacer
A6: Édition limitée
A7: Aucun
